Workbook

Sheet Read Me
A1: English 9 Pacing Calendar, 2026-27 (Purple and Gold days)
A2: Menchville High School. Lessons come from the English 9 Unit 1-7 instructional views. Day types come from the MHS Purple-Gold calendar; assessment windows come from the NNPS High School Testing Calendar.
A4: Tabs
A5: Year at a Glance: month grids colored like the Purple-Gold calendar. Each school day shows the lesson or assessment for the classes that meet that day. It fills itself from the Purple and Gold tabs, so do not type in it.
A6: Purple / Gold: one row per class meeting. The Lesson ID column (yellow) is the only column you need to edit. Unit, lesson, focus and standards fill in from the Lesson Bank.
A7: Lesson Bank: every lesson from the unit documents, plus the assessments and a Flex day. Add a row here to create a new lesson ID.
A8: Assessments: where each midquarter, benchmark and LPA landed for each track, inside its testing window. Its yellow Exam table (columns H and I) lists midyear exams, final exams and SOL test dates; each one is printed on its day in Year at a Glance.
A10: How to edit
A11: Change one day: click its Lesson ID cell and pick another ID from the dropdown.
A12: Push lessons back a day (snow day, assembly): on the Purple or Gold tab, select the Lesson ID cells from that day to the end of the list, cut (Ctrl+X), click the cell one row down and paste (Ctrl+V). Type FLEX or a new ID in the empty cell. Move any assessment rows back to their dates afterward.
A13: Add your own notes in the My notes column; it is not linked to anything.
A15: Colors
... A21: Purple ends with one Flex day because Purple has one fewer assessment on a regular day.

Sheet Year at a Glance
A1: English 9 Purple-Gold Pacing Calendar, August 2026 to June 2027
A2: Purple day | D2: Gold day | G2: Exam day | J2: Half day | M2: No school
A3: Each cell shows the date and the lesson for the classes that meet that day. Edit lessons on the Purple and Gold tabs.
A5: August 2026 | I5: September 2026 | Q5: October 2026
A6: S | B6: M | C6: T | D6: W | E6: T | F6: F | G6: S | I6: S | J6: M | K6: T | L6: W | M6: T | N6: F | O6: S | Q6: S | R6: M | S6: T | T6: W | U6: T | V6: F | W6: S
G7: 1 | K7: ="1"&CHAR(10)&IFERROR(VLOOKUP(DATE(2026,9,1),Purple!$A:$J,10,FALSE),"")&IFERROR(CHAR(10)&VLOOKUP(DATE(2026,9,1),Assessments!$H:$I,2,FALSE),"") | L7: ="2"&CHAR(10)&IFERROR(VLOOKUP(DATE(2026,9,2),Gold!$A:$J,10,FALSE),"")&IFERROR(CHAR(10)&VLOOKUP(DATE(2026,9,2),Assessments!$H:$I,2,FALSE),"") | M7: ="3"&CHAR(10)&IFERROR(VLOOKUP(DATE(2026,9,3),Purple!$A:$J,10,FALSE),"")&IFERROR(CHAR(10)&VLOOKUP(DATE(2026,9,3),Assessments!$H:$I,2,FALSE),"") | N7: 4 | O7: 5 | U7: ="1"&CHAR(10)&IFERROR(VLOOKUP(DATE(2026,10,1),Purple!$A:$J,10,FALSE),"")&IFERROR(CHAR(10)&VLOOKUP(DATE(2026,10,1),Assessments!$H:$I,2,FALSE),"") | V7: ="2"&CHAR(10)&IFERROR(VLOOKUP(DATE(2026,10,2),Gold!$A:$J,10,FALSE),"")&IFERROR(CHAR(10)&VLOOKUP(DATE(2026,10,2),Assessments!$H:$I,2,FALSE),"") | W7: 3
A8: 2 | B8: 3 | C8: 4 | D8: 5 | E8: 6 | F8: 7 | G8: 8 | I8: 6 | J8: 7 | K8: ="8"&CHAR(10)&IFERROR(VLOOKUP(DATE(2026,9,8),Gold!$A:$J,10,FALSE),"")&IFERROR(CHAR(10)&VLOOKUP(DATE(2026,9,8),Assessments!$H:$I,2,FALSE),"") | L8: ="9"&CHAR(10)&IFERROR(VLOOKUP(DATE(2026,9,9),Purple!$A:$J,10,FALSE),"")&IFERROR(CHAR(10)&VLOOKUP(DATE(2026,9,9),Assessments!$H:$I,2,FALSE),"") | M8: ="10"&CHAR(10)&IFERROR(VLOOKUP(DATE(2026,9,10),Gold!$A:$J,10,FALSE),"")&IFERROR(CHAR(10)&VLOOKUP(DATE(2026,9,10),Assessments!$H:$I,2,FALSE),"") | N8: ="11"&CHAR(10)&IFERROR(VLOOKUP(DATE(2026,9,11),Purple!$A:$J,10,FALSE),"")&IFERROR(CHAR(10)&VLOOKUP(DATE(2026,9,11),Assessments!$H:$I,2,FALSE),"") | O8: 12 | Q8: 4 | R8: ="5"&CHAR(10)&IFERROR(VLOOKUP(DATE(2026,10,5),Purple!$A:$J,10,FALSE),"")&IFERROR(CHAR(10)&VLOOKUP(DATE(2026,10,5),Assessments!$H:$I,2,FALSE),"") | S8: ="6"&CHAR(10)&IFERROR(VLOOKUP(DATE(2026,10,6),Gold!$A:$J,10,FALSE),"")&IFERROR(CHAR(10)&VLOOKUP(DATE(2026,10,6),Assessments!$H:$I,2,FALSE),"") | T8: ="7"&CHAR(10)&IFERROR(VLOOKUP(DATE(2026,10,7),Purple!$A:$J,10,FALSE),"")&IFERROR(CHAR(10)&VLOOKUP(DATE(2026,10,7),Assessments!$H:$I,2,FALSE),"") | U8: ="8"&CHAR(10)&IFERROR(VLOOKUP(DATE(2026,10,8),Gold!$A:$J,10,FALSE),"")&IFERROR(CHAR(10)&VLOOKUP(DATE(2026,10,8),Assessments!$H:$I,2,FALSE),"") | V8: ="9"&CHAR(10)&IFERROR(VLOOKUP(DATE(2026,10,9),Purple!$A:$J,10,FALSE),"")&IFERROR(CHAR(10)&VLOOKUP(DATE(2026,10,9),Assessments!$H:$I,2,FALSE),"") | W8: 10
A9: 9 | B9: 10 | C9: 11 | D9: 12 | E9: 13 | F9: 14 | G9: 15 | I9: 13 | J9: ="14"&CHAR(10)&IFERROR(VLOOKUP(DATE(2026,9,14),Gold!$A:$J,10,FALSE),"")&IFERROR(CHAR(10)&VLOOKUP(DATE(2026,9,14),Assessments!$H:$I,2,FALSE),"") | K9: ="15"&CHAR(10)&IFERROR(VLOOKUP(DATE(2026,9,15),Purple!$A:$J,10,FALSE),"")&IFERROR(CHAR(10)&VLOOKUP(DATE(2026,9,15),Assessments!$H:$I,2,FALSE),"") | L9: ="16"&CHAR(10)&IFERROR(VLOOKUP(DATE(2026,9,16),Gold!$A:$J,10,FALSE),"")&IFERROR(CHAR(10)&VLOOKUP(DATE(2026,9,16),Assessments!$H:$I,2,FALSE),"") | M9: ="17"&CHAR(10)&IFERROR(VLOOKUP(DATE(2026,9,17),Purple!$A:$J,10,FALSE),"")&IFERROR(CHAR(10)&VLOOKUP(DATE(2026,9,17),Assessments!$H:$I,2,FALSE),"") | N9: ="18"&CHAR(10)&IFERROR(VLOOKUP(DATE(2026,9,18),Gold!$A:$J,10,FALSE),"")&IFERROR(CHAR(10)&VLOOKUP(DATE(2026,9,18),Assessments!$H:$I,2,FALSE),"") | O9: 19 | Q9: 11 | R9: ="12"&CHAR(10)&IFERROR(VLOOKUP(DATE(2026,10,12),Gold!$A:$J,10,FALSE),"")&IFERROR(CHAR(10)&VLOOKUP(DATE(2026,10,12),Assessments!$H:$I,2,FALSE),"") | S9: ="13"&CHAR(10)&IFERROR(VLOOKUP(DATE(2026,10,13),Purple!$A:$J,10,FALSE),"")&IFERROR(CHAR(10)&VLOOKUP(DATE(2026,10,13),Assessments!$H:$I,2,FALSE),"") | T9: ="14"&CHAR(10)&IFERROR(VLOOKUP(DATE(2026,10,14),Gold!$A:$J,10,FALSE),"")&IFERROR(CHAR(10)&VLOOKUP(DATE(2026,10,14),Assessments!$H:$I,2,FALSE),"") | U9: ="15"&CHAR(10)&IFERROR(VLOOKUP(DATE(2026,10,15),Purple!$A:$J,10,FALSE),"")&IFERROR(CHAR(10)&VLOOKUP(DATE(2026,10,15),Assessments!$H:$I,2,FALSE),"") | V9: 16 | W9: 17
A10: 16 | B10: 17 | C10: 18 | D10: 19 | E10: 20 | F10: 21 | G10: 22 | I10: 20 | J10: ="21"&CHAR(10)&IFERROR(VLOOKUP(DATE(2026,9,21),Purple!$A:$J,10,FALSE),"")&IFERROR(CHAR(10)&VLOOKUP(DATE(2026,9,21),Assessments!$H:$I,2,FALSE),"") | K10: ="22"&CHAR(10)&IFERROR(VLOOKUP(DATE(2026,9,22),Gold!$A:$J,10,FALSE),"")&IFERROR(CHAR(10)&VLOOKUP(DATE(2026,9,22),Assessments!$H:$I,2,FALSE),"") | L10: ="23"&CHAR(10)&IFERROR(VLOOKUP(DATE(2026,9,23),Purple!$A:$J,10,FALSE),"")&IFERROR(CHAR(10)&VLOOKUP(DATE(2026,9,23),Assessments!$H:$I,2,FALSE),"") | M10: ="24"&CHAR(10)&IFERROR(VLOOKUP(DATE(2026,9,24),Gold!$A:$J,10,FALSE),"")&IFERROR(CHAR(10)&VLOOKUP(DATE(2026,9,24),Assessments!$H:$I,2,FALSE),"") | N10: ="25"&CHAR(10)&IFERROR(VLOOKUP(DATE(2026,9,25),Purple!$A:$J,10,FALSE),"")&IFERROR(CHAR(10)&VLOOKUP(DATE(2026,9,25),Assessments!$H:$I,2,FALSE),"") | O10: 26 | Q10: 18 | R10: ="19"&CHAR(10)&IFERROR(VLOOKUP(DATE(2026,10,19),Gold!$A:$J,10,FALSE),"")&IFERROR(CHAR(10)&VLOOKUP(DATE(2026,10,19),Assessments!$H:$I,2,FALSE),"") | S10: ="20"&CHAR(10)&IFERROR(VLOOKUP(DATE(2026,10,20),Purple!$A:$J,10,FALSE),"")&IFERROR(CHAR(10)&VLOOKUP(DATE(2026,10,20),Assessments!$H:$I,2,FALSE),"") | T10: ="21"&CHAR(10)&IFERROR(VLOOKUP(DATE(2026,10,21),Gold!$A:$J,10,FALSE),"")&IFERROR(CHAR(10)&VLOOKUP(DATE(2026,10,21),Assessments!$H:$I,2,FALSE),"") | U10: ="22"&CHAR(10)&IFERROR(VLOOKUP(DATE(2026,10,22),Purple!$A:$J,10,FALSE),"")&IFERROR(CHAR(10)&VLOOKUP(DATE(2026,10,22),Assessments!$H:$I,2,FALSE),"") | V10: ="23"&CHAR(10)&IFERROR(VLOOKUP(DATE(2026,10,23),Gold!$A:$J,10,FALSE),"")&IFERROR(CHAR(10)&VLOOKUP(DATE(2026,10,23),Assessments!$H:$I,2,FALSE),"") | W10: 24
A11: 23 | B11: ="24"&CHAR(10)&IFERROR(VLOOKUP(DATE(2026,8,24),Purple!$A:$J,10,FALSE),"")&IFERROR(CHAR(10)&VLOOKUP(DATE(2026,8,24),Assessments!$H:$I,2,FALSE),"") | C11: ="25"&CHAR(10)&IFERROR(VLOOKUP(DATE(2026,8,25),Gold!$A:$J,10,FALSE),"")&IFERROR(CHAR(10)&VLOOKUP(DATE(2026,8,25),Assessments!$H:$I,2,FALSE),"") | D11: ="26"&CHAR(10)&IFERROR(VLOOKUP(DATE(2026,8,26),Purple!$A:$J,10,FALSE),"")&IFERROR(CHAR(10)&VLOOKUP(DATE(2026,8,26),Assessments!$H:$I,2,FALSE),"") | E11: ="27"&CHAR(10)&IFERROR(VLOOKUP(DATE(2026,8,27),Gold!$A:$J,10,FALSE),"")&IFERROR(CHAR(10)&VLOOKUP(DATE(2026,8,27),Assessments!$H:$I,2,FALSE),"") | F11: ="28"&CHAR(10)&IFERROR(VLOOKUP(DATE(2026,8,28),Purple!$A:$J,10,FALSE),"")&IFERROR(CHAR(10)&VLOOKUP(DATE(2026,8,28),Assessments!$H:$I,2,FALSE),"") | G11: 29 | I11: 27 | J11: ="28"&CHAR(10)&IFERROR(VLOOKUP(DATE(2026,9,28),Gold!$A:$J,10,FALSE),"")&IFERROR(CHAR(10)&VLOOKUP(DATE(2026,9,28),Assessments!$H:$I,2,FALSE),"") | K11: ="29"&CHAR(10)&IFERROR(VLOOKUP(DATE(2026,9,29),Purple!$A:$J,10,FALSE),"")&IFERROR(CHAR(10)&VLOOKUP(DATE(2026,9,29),Assessments!$H:$I,2,FALSE),"") | L11: ="30"&CHAR(10)&IFERROR(VLOOKUP(DATE(2026,9,30),Gold!$A:$J,10,FALSE),"")&IFERROR(CHAR(10)&VLOOKUP(DATE(2026,9,30),Assessments!$H:$I,2,FALSE),"") | Q11: 25 | R11: ="26"&CHAR(10)&IFERROR(VLOOKUP(DATE(2026,10,26),Purple!$A:$J,10,FALSE),"")&IFERROR(CHAR(10)&VLOOKUP(DATE(2026,10,26),Assessments!$H:$I,2,FALSE),"") | S11: ="27"&CHAR(10)&IFERROR(VLOOKUP(DATE(2026,10,27),Gold!$A:$J,10,FALSE),"")&IFERROR(CHAR(10)&VLOOKUP(DATE(2026,10,27),Assessments!$H:$I,2,FALSE),"") | T11: ="28"&CHAR(10)&IFERROR(VLOOKUP(DATE(2026,10,28),Purple!$A:$J,10,FALSE),"")&IFERROR(CHAR(10)&VLOOKUP(DATE(2026,10,28),Assessments!$H:$I,2,FALSE),"") | U11: ="29"&CHAR(10)&IFERROR(VLOOKUP(DATE(2026,10,29),Gold!$A:$J,10,FALSE),"")&IFERROR(CHAR(10)&VLOOKUP(DATE(2026,10,29),Assessments!$H:$I,2,FALSE),"") | V11: ="30"&CHAR(10)&IFERROR(VLOOKUP(DATE(2026,10,30),Purple!$A:$J,10,FALSE),"")&IFERROR(CHAR(10)&VLOOKUP(DATE(2026,10,30),Assessments!$H:$I,2,FALSE),"") | W11: 31
A12: 30 | B12: ="31"&CHAR(10)&IFERROR(VLOOKUP(DATE(2026,8,31),Gold!$A:$J,10,FALSE),"")&IFERROR(CHAR(10)&VLOOKUP(DATE(2026,8,31),Assessments!$H:$I,2,FALSE),"")
A14: November 2026 | I14: December 2026 | Q14: January 2027
A15: S | B15: M | C15: T | D15: W | E15: T | F15: F | G15: S | I15: S | J15: M | K15: T | L15: W | M15: T | N15: F | O15: S | Q15: S | R15: M | S15: T | T15: W | U15: T | V15: F | W15: S
A16: 1 | B16: ="2"&CHAR(10)&IFERROR(VLOOKUP(DATE(2026,11,2),Gold!$A:$J,10,FALSE),"")&IFERROR(CHAR(10)&VLOOKUP(DATE(2026,11,2),Assessments!$H:$I,2,FALSE),"") | C16: 3 | D16: ="4"&CHAR(10)&IFERROR(VLOOKUP(DATE(2026,11,4),Purple!$A:$J,10,FALSE),"")&IFERROR(CHAR(10)&VLOOKUP(DATE(2026,11,4),Assessments!$H:$I,2,FALSE),"") | E16: ="5"&CHAR(10)&IFERROR(VLOOKUP(DATE(2026,11,5),Gold!$A:$J,10,FALSE),"")&IFERROR(CHAR(10)&VLOOKUP(DATE(2026,11,5),Assessments!$H:$I,2,FALSE),"") | F16: ="6"&CHAR(10)&IFERROR(VLOOKUP(DATE(2026,11,6),Purple!$A:$J,10,FALSE),"")&IFERROR(CHAR(10)&VLOOKUP(DATE(2026,11,6),Assessments!$H:$I,2,FALSE),"") | G16: 7 | K16: ="1"&CHAR(10)&IFERROR(VLOOKUP(DATE(2026,12,1),Purple!$A:$J,10,FALSE),"")&IFERROR(CHAR(10)&VLOOKUP(DATE(2026,12,1),Assessments!$H:$I,2,FALSE),"") | L16: ="2"&CHAR(10)&IFERROR(VLOOKUP(DATE(2026,12,2),Gold!$A:$J,10,FALSE),"")&IFERROR(CHAR(10)&VLOOKUP(DATE(2026,12,2),Assessments!$H:$I,2,FALSE),"") | M16: ="3"&CHAR(10)&IFERROR(VLOOKUP(DATE(2026,12,3),Purple!$A:$J,10,FALSE),"")&IFERROR(CHAR(10)&VLOOKUP(DATE(2026,12,3),Assessments!$H:$I,2,FALSE),"") | N16: ="4"&CHAR(10)&IFERROR(VLOOKUP(DATE(2026,12,4),Gold!$A:$J,10,FALSE),"")&IFERROR(CHAR(10)&VLOOKUP(DATE(2026,12,4),Assessments!$H:$I,2,FALSE),"") | O16: 5 | V16: 1 | W16: 2
A17: 8 | B17: ="9"&CHAR(10)&IFERROR(VLOOKUP(DATE(2026,11,9),Gold!$A:$J,10,FALSE),"")&IFERROR(CHAR(10)&VLOOKUP(DATE(2026,11,9),Assessments!$H:$I,2,FALSE),"") | C17: ="10"&CHAR(10)&IFERROR(VLOOKUP(DATE(2026,11,10),Purple!$A:$J,10,FALSE),"")&IFERROR(CHAR(10)&VLOOKUP(DATE(2026,11,10),Assessments!$H:$I,2,FALSE),"") | D17: ="11"&CHAR(10)&IFERROR(VLOOKUP(DATE(2026,11,11),Gold!$A:$J,10,FALSE),"")&IFERROR(CHAR(10)&VLOOKUP(DATE(2026,11,11),Assessments!$H:$I,2,FALSE),"") | E17: ="12"&CHAR(10)&IFERROR(VLOOKUP(DATE(2026,11,12),Purple!$A:$J,10,FALSE),"")&IFERROR(CHAR(10)&VLOOKUP(DATE(2026,11,12),Assessments!$H:$I,2,FALSE),"") | F17: ="13"&CHAR(10)&IFERROR(VLOOKUP(DATE(2026,11,13),Gold!$A:$J,10,FALSE),"")&IFERROR(CHAR(10)&VLOOKUP(DATE(2026,11,13),Assessments!$H:$I,2,FALSE),"") | G17: 14 | I17: 6 | J17: ="7"&CHAR(10)&IFERROR(VLOOKUP(DATE(2026,12,7),Purple!$A:$J,10,FALSE),"")&IFERROR(CHAR(10)&VLOOKUP(DATE(2026,12,7),Assessments!$H:$I,2,FALSE),"") | K17: ="8"&CHAR(10)&IFERROR(VLOOKUP(DATE(2026,12,8),Gold!$A:$J,10,FALSE),"")&IFERROR(CHAR(10)&VLOOKUP(DATE(2026,12,8),Assessments!$H:$I,2,FALSE),"") | L17: ="9"&CHAR(10)&IFERROR(VLOOKUP(DATE(2026,12,9),Purple!$A:$J,10,FALSE),"")&IFERROR(CHAR(10)&VLOOKUP(DATE(2026,12,9),Assessments!$H:$I,2,FALSE),"") | M17: ="10"&CHAR(10)&IFERROR(VLOOKUP(DATE(2026,12,10),Gold!$A:$J,10,FALSE),"")&IFERROR(CHAR(10)&VLOOKUP(DATE(2026,12,10),Assessments!$H:$I,2,FALSE),"") | N17: ="11"&CHAR(10)&IFERROR(VLOOKUP(DATE(2026,12,11),Purple!$A:$J,10,FALSE),"")&IFERROR(CHAR(10)&VLOOKUP(DATE(2026,12,11),Assessments!$H:$I,2,FALSE),"") | O17: 12 | Q17: 3 | R17: 4 | S17: ="5"&CHAR(10)&IFERROR(VLOOKUP(DATE(2027,1,5),Purple!$A:$J,10,FALSE),"")&IFERROR(CHAR(10)&VLOOKUP(DATE(2027,1,5),Assessments!$H:$I,2,FALSE),"") | T17: ="6"&CHAR(10)&IFERROR(VLOOKUP(DATE(2027,1,6),Gold!$A:$J,10,FALSE),"")&IFERROR(CHAR(10)&VLOOKUP(DATE(2027,1,6),Assessments!$H:$I,2,FALSE),"") | U17: ="7"&CHAR(10)&IFERROR(VLOOKUP(DATE(2027,1,7),Purple!$A:$J,10,FALSE),"")&IFERROR(CHAR(10)&VLOOKUP(DATE(2027,1,7),Assessments!$H:$I,2,FALSE),"") | V17: ="8"&CHAR(10)&IFERROR(VLOOKUP(DATE(2027,1,8),Gold!$A:$J,10,FALSE),"")&IFERROR(CHAR(10)&VLOOKUP(DATE(2027,1,8),Assessments!$H:$I,2,FALSE),"") | W17: 9
A18: 15 | B18: ="16"&CHAR(10)&IFERROR(VLOOKUP(DATE(2026,11,16),Purple!$A:$J,10,FALSE),"")&IFERROR(CHAR(10)&VLOOKUP(DATE(2026,11,16),Assessments!$H:$I,2,FALSE),"") | C18: ="17"&CHAR(10)&IFERROR(VLOOKUP(DATE(2026,11,17),Gold!$A:$J,10,FALSE),"")&IFERROR(CHAR(10)&VLOOKUP(DATE(2026,11,17),Assessments!$H:$I,2,FALSE),"") | D18: ="18"&CHAR(10)&IFERROR(VLOOKUP(DATE(2026,11,18),Purple!$A:$J,10,FALSE),"")&IFERROR(CHAR(10)&VLOOKUP(DATE(2026,11,18),Assessments!$H:$I,2,FALSE),"") | E18: ="19"&CHAR(10)&IFERROR(VLOOKUP(DATE(2026,11,19),Gold!$A:$J,10,FALSE),"")&IFERROR(CHAR(10)&VLOOKUP(DATE(2026,11,19),Assessments!$H:$I,2,FALSE),"") | F18: ="20"&CHAR(10)&IFERROR(VLOOKUP(DATE(2026,11,20),Purple!$A:$J,10,FALSE),"")&IFERROR(CHAR(10)&VLOOKUP(DATE(2026,11,20),Assessments!$H:$I,2,FALSE),"") | G18: 21 | I18: 13 | J18: ="14"&CHAR(10)&IFERROR(VLOOKUP(DATE(2026,12,14),Gold!$A:$J,10,FALSE),"")&IFERROR(CHAR(10)&VLOOKUP(DATE(2026,12,14),Assessments!$H:$I,2,FALSE),"") | K18: ="15"&CHAR(10)&IFERROR(VLOOKUP(DATE(2026,12,15),Purple!$A:$J,10,FALSE),"")&IFERROR(CHAR(10)&VLOOKUP(DATE(2026,12,15),Assessments!$H:$I,2,FALSE),"") | L18: ="16"&CHAR(10)&IFERROR(VLOOKUP(DATE(2026,12,16),Gold!$A:$J,10,FALSE),"")&IFERROR(CHAR(10)&VLOOKUP(DATE(2026,12,16),Assessments!$H:$I,2,FALSE),"") | M18: ="17"&CHAR(10)&IFERROR(VLOOKUP(DATE(2026,12,17),Purple!$A:$J,10,FALSE),"")&IFERROR(CHAR(10)&VLOOKUP(DATE(2026,12,17),Assessments!$H:$I,2,FALSE),"") | N18: ="18"&CHAR(10)&IFERROR(VLOOKUP(DATE(2026,12,18),Gold!$A:$J,10,FALSE),"")&IFERROR(CHAR(10)&VLOOKUP(DATE(2026,12,18),Assessments!$H:$I,2,FALSE),"") | O18: 19 | Q18: 10 | R18: ="11"&CHAR(10)&IFERROR(VLOOKUP(DATE(2027,1,11),Purple!$A:$J,10,FALSE),"")&IFERROR(CHAR(10)&VLOOKUP(DATE(2027,1,11),Assessments!$H:$I,2,FALSE),"") | S18: ="12"&CHAR(10)&IFERROR(VLOOKUP(DATE(2027,1,12),Gold!$A:$J,10,FALSE),"")&IFERROR(CHAR(10)&VLOOKUP(DATE(2027,1,12),Assessments!$H:$I,2,FALSE),"") | T18: ="13"&CHAR(10)&IFERROR(VLOOKUP(DATE(2027,1,13),Purple!$A:$J,10,FALSE),"")&IFERROR(CHAR(10)&VLOOKUP(DATE(2027,1,13),Assessments!$H:$I,2,FALSE),"") | U18: ="14"&CHAR(10)&IFERROR(VLOOKUP(DATE(2027,1,14),Gold!$A:$J,10,FALSE),"")&IFERROR(CHAR(10)&VLOOKUP(DATE(2027,1,14),Assessments!$H:$I,2,FALSE),"") | V18: ="15"&CHAR(10)&IFERROR(VLOOKUP(DATE(2027,1,15),Purple!$A:$J,10,FALSE),"")&IFERROR(CHAR(10)&VLOOKUP(DATE(2027,1,15),Assessments!$H:$I,2,FALSE),"") | W18: 16
A19: 22 | B19: ="23"&CHAR(10)&IFERROR(VLOOKUP(DATE(2026,11,23),Gold!$A:$J,10,FALSE),"")&IFERROR(CHAR(10)&VLOOKUP(DATE(2026,11,23),Assessments!$H:$I,2,FALSE),"") | C19: ="24"&CHAR(10)&IFERROR(VLOOKUP(DATE(2026,11,24),Purple!$A:$J,10,FALSE),"")&IFERROR(CHAR(10)&VLOOKUP(DATE(2026,11,24),Assessments!$H:$I,2,FALSE),"") | D19: 25 | E19: 26 | F19: 27 | G19: 28 | I19: 20 | J19: 21 | K19: 22 | L19: 23 | M19: 24 | N19: 25 | O19: 26 | Q19: 17 | R19: 18 | S19: ="19"&CHAR(10)&IFERROR(VLOOKUP(DATE(2027,1,19),Gold!$A:$J,10,FALSE),"")&IFERROR(CHAR(10)&VLOOKUP(DATE(2027,1,19),Assessments!$H:$I,2,FALSE),"") | T19: ="20"&IFERROR(CHAR(10)&"P: "&VLOOKUP(DATE(2027,1,20),Purple!$A:$J,10,FALSE),"")&IFERROR(CHAR(10)&"G: "&VLOOKUP(DATE(2027,1,20),Gold!$A:$J,10,FALSE),"")&IFERROR(CHAR(10)&VLOOKUP(DATE(2027,1,20),Assessments!$H:$I,2,FALSE),CHAR(10)&"Exam day") | U19: ="21"&IFERROR(CHAR(10)&"P: "&VLOOKUP(DATE(2027,1,21),Purple!$A:$J,10,FALSE),"")&IFERROR(CHAR(10)&"G: "&VLOOKUP(DATE(2027,1,21),Gold!$A:$J,10,FALSE),"")&IFERROR(CHAR(10)&VLOOKUP(DATE(2027,1,21),Assessments!$H:$I,2,FALSE),CHAR(10)&"Exam day") | V19: ="22"&IFERROR(CHAR(10)&"P: "&VLOOKUP(DATE(2027,1,22),Purple!$A:$J,10,FALSE),"")&IFERROR(CHAR(10)&"G: "&VLOOKUP(DATE(2027,1,22),Gold!$A:$J,10,FALSE),"")&IFERROR(CHAR(10)&VLOOKUP(DATE(2027,1,22),Assessments!$H:$I,2,FALSE),CHAR(10)&"Exam day") | W19: 23
A20: 29 | B20: ="30"&CHAR(10)&IFERROR(VLOOKUP(DATE(2026,11,30),Gold!$A:$J,10,FALSE),"")&IFERROR(CHAR(10)&VLOOKUP(DATE(2026,11,30),Assessments!$H:$I,2,FALSE),"") | I20: 27 | J20: 28 | K20: 29 | L20: 30 | M20: 31 | Q20: 24 | R20: 25 | S20: 26 | T20: ="27"&CHAR(10)&IFERROR(VLOOKUP(DATE(2027,1,27),Purple!$A:$J,10,FALSE),"")&IFERROR(CHAR(10)&VLOOKUP(DATE(2027,1,27),Assessments!$H:$I,2,FALSE),"") | U20: ="28"&CHAR(10)&IFERROR(VLOOKUP(DATE(2027,1,28),Gold!$A:$J,10,FALSE),"")&IFERROR(CHAR(10)&VLOOKUP(DATE(2027,1,28),Assessments!$H:$I,2,FALSE),"") | V20: ="29"&CHAR(10)&IFERROR(VLOOKUP(DATE(2027,1,29),Purple!$A:$J,10,FALSE),"")&IFERROR(CHAR(10)&VLOOKUP(DATE(2027,1,29),Assessments!$H:$I,2,FALSE),"") | W20: 30
Q21: 31
A23: February 2027 | I23: March 2027 | Q23: April 2027
A24: S | B24: M | C24: T | D24: W | E24: T | F24: F | G24: S | I24: S | J24: M | K24: T | L24: W | M24: T | N24: F | O24: S | Q24: S | R24: M | S24: T | T24: W | U24: T | V24: F | W24: S
B25: ="1"&CHAR(10)&IFERROR(VLOOKUP(DATE(2027,2,1),Gold!$A:$J,10,FALSE),"")&IFERROR(CHAR(10)&VLOOKUP(DATE(2027,2,1),Assessments!$H:$I,2,FALSE),"") | C25: ="2"&CHAR(10)&IFERROR(VLOOKUP(DATE(2027,2,2),Purple!$A:$J,10,FALSE),"")&IFERROR(CHAR(10)&VLOOKUP(DATE(2027,2,2),Assessments!$H:$I,2,FALSE),"") | D25: ="3"&CHAR(10)&IFERROR(VLOOKUP(DATE(2027,2,3),Gold!$A:$J,10,FALSE),"")&IFERROR(CHAR(10)&VLOOKUP(DATE(2027,2,3),Assessments!$H:$I,2,FALSE),"") | E25: ="4"&CHAR(10)&IFERROR(VLOOKUP(DATE(2027,2,4),Purple!$A:$J,10,FALSE),"")&IFERROR(CHAR(10)&VLOOKUP(DATE(2027,2,4),Assessments!$H:$I,2,FALSE),"") | F25: ="5"&CHAR(10)&IFERROR(VLOOKUP(DATE(2027,2,5),Gold!$A:$J,10,FALSE),"")&IFERROR(CHAR(10)&VLOOKUP(DATE(2027,2,5),Assessments!$H:$I,2,FALSE),"") | G25: 6 | J25: ="1"&CHAR(10)&IFERROR(VLOOKUP(DATE(2027,3,1),Purple!$A:$J,10,FALSE),"")&IFERROR(CHAR(10)&VLOOKUP(DATE(2027,3,1),Assessments!$H:$I,2,FALSE),"") | K25: ="2"&CHAR(10)&IFERROR(VLOOKUP(DATE(2027,3,2),Gold!$A:$J,10,FALSE),"")&IFERROR(CHAR(10)&VLOOKUP(DATE(2027,3,2),Assessments!$H:$I,2,FALSE),"") | L25: ="3"&CHAR(10)&IFERROR(VLOOKUP(DATE(2027,3,3),Purple!$A:$J,10,FALSE),"")&IFERROR(CHAR(10)&VLOOKUP(DATE(2027,3,3),Assessments!$H:$I,2,FALSE),"") | M25: ="4"&CHAR(10)&IFERROR(VLOOKUP(DATE(2027,3,4),Gold!$A:$J,10,FALSE),"")&IFERROR(CHAR(10)&VLOOKUP(DATE(2027,3,4),Assessments!$H:$I,2,FALSE),"") | N25: ="5"&CHAR(10)&IFERROR(VLOOKUP(DATE(2027,3,5),Purple!$A:$J,10,FALSE),"")&IFERROR(CHAR(10)&VLOOKUP(DATE(2027,3,5),Assessments!$H:$I,2,FALSE),"") | O25: 6 | U25: ="1"&CHAR(10)&IFERROR(VLOOKUP(DATE(2027,4,1),Gold!$A:$J,10,FALSE),"")&IFERROR(CHAR(10)&VLOOKUP(DATE(2027,4,1),Assessments!$H:$I,2,FALSE),"") | V25: ="2"&CHAR(10)&IFERROR(VLOOKUP(DATE(2027,4,2),Purple!$A:$J,10,FALSE),"")&IFERROR(CHAR(10)&VLOOKUP(DATE(2027,4,2),Assessments!$H:$I,2,FALSE),"") | W25: 3
A26: 7 | B26: ="8"&CHAR(10)&IFERROR(VLOOKUP(DATE(2027,2,8),Purple!$A:$J,10,FALSE),"")&IFERROR(CHAR(10)&VLOOKUP(DATE(2027,2,8),Assessments!$H:$I,2,FALSE),"") | C26: ="9"&CHAR(10)&IFERROR(VLOOKUP(DATE(2027,2,9),Gold!$A:$J,10,FALSE),"")&IFERROR(CHAR(10)&VLOOKUP(DATE(2027,2,9),Assessments!$H:$I,2,FALSE),"") | D26: ="10"&CHAR(10)&IFERROR(VLOOKUP(DATE(2027,2,10),Purple!$A:$J,10,FALSE),"")&IFERROR(CHAR(10)&VLOOKUP(DATE(2027,2,10),Assessments!$H:$I,2,FALSE),"") | E26: ="11"&CHAR(10)&IFERROR(VLOOKUP(DATE(2027,2,11),Gold!$A:$J,10,FALSE),"")&IFERROR(CHAR(10)&VLOOKUP(DATE(2027,2,11),Assessments!$H:$I,2,FALSE),"") | F26: ="12"&CHAR(10)&IFERROR(VLOOKUP(DATE(2027,2,12),Purple!$A:$J,10,FALSE),"")&IFERROR(CHAR(10)&VLOOKUP(DATE(2027,2,12),Assessments!$H:$I,2,FALSE),"") | G26: 13 | I26: 7 | J26: ="8"&CHAR(10)&IFERROR(VLOOKUP(DATE(2027,3,8),Gold!$A:$J,10,FALSE),"")&IFERROR(CHAR(10)&VLOOKUP(DATE(2027,3,8),Assessments!$H:$I,2,FALSE),"") | K26: ="9"&CHAR(10)&IFERROR(VLOOKUP(DATE(2027,3,9),Purple!$A:$J,10,FALSE),"")&IFERROR(CHAR(10)&VLOOKUP(DATE(2027,3,9),Assessments!$H:$I,2,FALSE),"") | L26: ="10"&CHAR(10)&IFERROR(VLOOKUP(DATE(2027,3,10),Gold!$A:$J,10,FALSE),"")&IFERROR(CHAR(10)&VLOOKUP(DATE(2027,3,10),Assessments!$H:$I,2,FALSE),"") | M26: ="11"&CHAR(10)&IFERROR(VLOOKUP(DATE(2027,3,11),Purple!$A:$J,10,FALSE),"")&IFERROR(CHAR(10)&VLOOKUP(DATE(2027,3,11),Assessments!$H:$I,2,FALSE),"") | N26: ="12"&CHAR(10)&IFERROR(VLOOKUP(DATE(2027,3,12),Gold!$A:$J,10,FALSE),"")&IFERROR(CHAR(10)&VLOOKUP(DATE(2027,3,12),Assessments!$H:$I,2,FALSE),"") | O26: 13 | Q26: 4 | R26: 5 | S26: 6 | T26: 7 | U26: 8 | V26: 9 | W26: 10
A27: 14 | B27: 15 | C27: ="16"&CHAR(10)&IFERROR(VLOOKUP(DATE(2027,2,16),Gold!$A:$J,10,FALSE),"")&IFERROR(CHAR(10)&VLOOKUP(DATE(2027,2,16),Assessments!$H:$I,2,FALSE),"") | D27: ="17"&CHAR(10)&IFERROR(VLOOKUP(DATE(2027,2,17),Purple!$A:$J,10,FALSE),"")&IFERROR(CHAR(10)&VLOOKUP(DATE(2027,2,17),Assessments!$H:$I,2,FALSE),"") | E27: ="18"&CHAR(10)&IFERROR(VLOOKUP(DATE(2027,2,18),Gold!$A:$J,10,FALSE),"")&IFERROR(CHAR(10)&VLOOKUP(DATE(2027,2,18),Assessments!$H:$I,2,FALSE),"") | F27: ="19"&CHAR(10)&IFERROR(VLOOKUP(DATE(2027,2,19),Purple!$A:$J,10,FALSE),"")&IFERROR(CHAR(10)&VLOOKUP(DATE(2027,2,19),Assessments!$H:$I,2,FALSE),"") | G27: 20 | I27: 14 | J27: ="15"&CHAR(10)&IFERROR(VLOOKUP(DATE(2027,3,15),Purple!$A:$J,10,FALSE),"")&IFERROR(CHAR(10)&VLOOKUP(DATE(2027,3,15),Assessments!$H:$I,2,FALSE),"") | K27: ="16"&CHAR(10)&IFERROR(VLOOKUP(DATE(2027,3,16),Gold!$A:$J,10,FALSE),"")&IFERROR(CHAR(10)&VLOOKUP(DATE(2027,3,16),Assessments!$H:$I,2,FALSE),"") | L27: ="17"&CHAR(10)&IFERROR(VLOOKUP(DATE(2027,3,17),Purple!$A:$J,10,FALSE),"")&IFERROR(CHAR(10)&VLOOKUP(DATE(2027,3,17),Assessments!$H:$I,2,FALSE),"") | M27: ="18"&CHAR(10)&IFERROR(VLOOKUP(DATE(2027,3,18),Gold!$A:$J,10,FALSE),"")&IFERROR(CHAR(10)&VLOOKUP(DATE(2027,3,18),Assessments!$H:$I,2,FALSE),"") | N27: ="19"&CHAR(10)&IFERROR(VLOOKUP(DATE(2027,3,19),Purple!$A:$J,10,FALSE),"")&IFERROR(CHAR(10)&VLOOKUP(DATE(2027,3,19),Assessments!$H:$I,2,FALSE),"") | O27: 20 | Q27: 11 | R27: 12 | S27: ="13"&CHAR(10)&IFERROR(VLOOKUP(DATE(2027,4,13),Gold!$A:$J,10,FALSE),"")&IFERROR(CHAR(10)&VLOOKUP(DATE(2027,4,13),Assessments!$H:$I,2,FALSE),"") | T27: ="14"&CHAR(10)&IFERROR(VLOOKUP(DATE(2027,4,14),Purple!$A:$J,10,FALSE),"")&IFERROR(CHAR(10)&VLOOKUP(DATE(2027,4,14),Assessments!$H:$I,2,FALSE),"") | U27: ="15"&CHAR(10)&IFERROR(VLOOKUP(DATE(2027,4,15),Gold!$A:$J,10,FALSE),"")&IFERROR(CHAR(10)&VLOOKUP(DATE(2027,4,15),Assessments!$H:$I,2,FALSE),"") | V27: ="16"&CHAR(10)&IFERROR(VLOOKUP(DATE(2027,4,16),Purple!$A:$J,10,FALSE),"")&IFERROR(CHAR(10)&VLOOKUP(DATE(2027,4,16),Assessments!$H:$I,2,FALSE),"") | W27: 17
A28: 21 | B28: ="22"&CHAR(10)&IFERROR(VLOOKUP(DATE(2027,2,22),Gold!$A:$J,10,FALSE),"")&IFERROR(CHAR(10)&VLOOKUP(DATE(2027,2,22),Assessments!$H:$I,2,FALSE),"") | C28: ="23"&CHAR(10)&IFERROR(VLOOKUP(DATE(2027,2,23),Purple!$A:$J,10,FALSE),"")&IFERROR(CHAR(10)&VLOOKUP(DATE(2027,2,23),Assessments!$H:$I,2,FALSE),"") | D28: ="24"&CHAR(10)&IFERROR(VLOOKUP(DATE(2027,2,24),Gold!$A:$J,10,FALSE),"")&IFERROR(CHAR(10)&VLOOKUP(DATE(2027,2,24),Assessments!$H:$I,2,FALSE),"") | E28: ="25"&CHAR(10)&IFERROR(VLOOKUP(DATE(2027,2,25),Purple!$A:$J,10,FALSE),"")&IFERROR(CHAR(10)&VLOOKUP(DATE(2027,2,25),Assessments!$H:$I,2,FALSE),"") | F28: ="26"&CHAR(10)&IFERROR(VLOOKUP(DATE(2027,2,26),Gold!$A:$J,10,FALSE),"")&IFERROR(CHAR(10)&VLOOKUP(DATE(2027,2,26),Assessments!$H:$I,2,FALSE),"") | G28: 27 | I28: 21 | J28: ="22"&CHAR(10)&IFERROR(VLOOKUP(DATE(2027,3,22),Gold!$A:$J,10,FALSE),"")&IFERROR(CHAR(10)&VLOOKUP(DATE(2027,3,22),Assessments!$H:$I,2,FALSE),"") | K28: ="23"&CHAR(10)&IFERROR(VLOOKUP(DATE(2027,3,23),Purple!$A:$J,10,FALSE),"")&IFERROR(CHAR(10)&VLOOKUP(DATE(2027,3,23),Assessments!$H:$I,2,FALSE),"") | L28: ="24"&CHAR(10)&IFERROR(VLOOKUP(DATE(2027,3,24),Gold!$A:$J,10,FALSE),"")&IFERROR(CHAR(10)&VLOOKUP(DATE(2027,3,24),Assessments!$H:$I,2,FALSE),"") | M28: ="25"&CHAR(10)&IFERROR(VLOOKUP(DATE(2027,3,25),Purple!$A:$J,10,FALSE),"")&IFERROR(CHAR(10)&VLOOKUP(DATE(2027,3,25),Assessments!$H:$I,2,FALSE),"") | N28: ="26"&CHAR(10)&IFERROR(VLOOKUP(DATE(2027,3,26),Gold!$A:$J,10,FALSE),"")&IFERROR(CHAR(10)&VLOOKUP(DATE(2027,3,26),Assessments!$H:$I,2,FALSE),"") | O28: 27 | Q28: 18 | R28: ="19"&CHAR(10)&IFERROR(VLOOKUP(DATE(2027,4,19),Gold!$A:$J,10,FALSE),"")&IFERROR(CHAR(10)&VLOOKUP(DATE(2027,4,19),Assessments!$H:$I,2,FALSE),"") | S28: ="20"&CHAR(10)&IFERROR(VLOOKUP(DATE(2027,4,20),Purple!$A:$J,10,FALSE),"")&IFERROR(CHAR(10)&VLOOKUP(DATE(2027,4,20),Assessments!$H:$I,2,FALSE),"") | T28: ="21"&CHAR(10)&IFERROR(VLOOKUP(DATE(2027,4,21),Gold!$A:$J,10,FALSE),"")&IFERROR(CHAR(10)&VLOOKUP(DATE(2027,4,21),Assessments!$H:$I,2,FALSE),"") | U28: ="22"&CHAR(10)&IFERROR(VLOOKUP(DATE(2027,4,22),Purple!$A:$J,10,FALSE),"")&IFERROR(CHAR(10)&VLOOKUP(DATE(2027,4,22),Assessments!$H:$I,2,FALSE),"") | V28: ="23"&CHAR(10)&IFERROR(VLOOKUP(DATE(2027,4,23),Gold!$A:$J,10,FALSE),"")&IFERROR(CHAR(10)&VLOOKUP(DATE(2027,4,23),Assessments!$H:$I,2,FALSE),"") | W28: 24
A29: 28 | I29: 28 | J29: ="29"&CHAR(10)&IFERROR(VLOOKUP(DATE(2027,3,29),Purple!$A:$J,10,FALSE),"")&IFERROR(CHAR(10)&VLOOKUP(DATE(2027,3,29),Assessments!$H:$I,2,FALSE),"") | K29: ="30"&CHAR(10)&IFERROR(VLOOKUP(DATE(2027,3,30),Gold!$A:$J,10,FALSE),"")&IFERROR(CHAR(10)&VLOOKUP(DATE(2027,3,30),Assessments!$H:$I,2,FALSE),"") | L29: ="31"&CHAR(10)&IFERROR(VLOOKUP(DATE(2027,3,31),Purple!$A:$J,10,FALSE),"")&IFERROR(CHAR(10)&VLOOKUP(DATE(2027,3,31),Assessments!$H:$I,2,FALSE),"") | Q29: 25 | R29: ="26"&CHAR(10)&IFERROR(VLOOKUP(DATE(2027,4,26),Purple!$A:$J,10,FALSE),"")&IFERROR(CHAR(10)&VLOOKUP(DATE(2027,4,26),Assessments!$H:$I,2,FALSE),"") | S29: ="27"&CHAR(10)&IFERROR(VLOOKUP(DATE(2027,4,27),Gold!$A:$J,10,FALSE),"")&IFERROR(CHAR(10)&VLOOKUP(DATE(2027,4,27),Assessments!$H:$I,2,FALSE),"") | T29: ="28"&CHAR(10)&IFERROR(VLOOKUP(DATE(2027,4,28),Purple!$A:$J,10,FALSE),"")&IFERROR(CHAR(10)&VLOOKUP(DATE(2027,4,28),Assessments!$H:$I,2,FALSE),"") | U29: ="29"&CHAR(10)&IFERROR(VLOOKUP(DATE(2027,4,29),Gold!$A:$J,10,FALSE),"")&IFERROR(CHAR(10)&VLOOKUP(DATE(2027,4,29),Assessments!$H:$I,2,FALSE),"") | V29: ="30"&CHAR(10)&IFERROR(VLOOKUP(DATE(2027,4,30),Purple!$A:$J,10,FALSE),"")&IFERROR(CHAR(10)&VLOOKUP(DATE(2027,4,30),Assessments!$H:$I,2,FALSE),"")
A32: May 2027 | I32: June 2027
A33: S | B33: M | C33: T | D33: W | E33: T | F33: F | G33: S | I33: S | J33: M | K33: T | L33: W | M33: T | N33: F | O33: S
G34: 1 | K34: ="1"&CHAR(10)&IFERROR(VLOOKUP(DATE(2027,6,1),Gold!$A:$J,10,FALSE),"")&IFERROR(CHAR(10)&VLOOKUP(DATE(2027,6,1),Assessments!$H:$I,2,FALSE),"") | L34: ="2"&CHAR(10)&IFERROR(VLOOKUP(DATE(2027,6,2),Purple!$A:$J,10,FALSE),"")&IFERROR(CHAR(10)&VLOOKUP(DATE(2027,6,2),Assessments!$H:$I,2,FALSE),"") | M34: ="3"&CHAR(10)&IFERROR(VLOOKUP(DATE(2027,6,3),Gold!$A:$J,10,FALSE),"")&IFERROR(CHAR(10)&VLOOKUP(DATE(2027,6,3),Assessments!$H:$I,2,FALSE),"") | N34: ="4"&IFERROR(CHAR(10)&"P: "&VLOOKUP(DATE(2027,6,4),Purple!$A:$J,10,FALSE),"")&IFERROR(CHAR(10)&"G: "&VLOOKUP(DATE(2027,6,4),Gold!$A:$J,10,FALSE),"")&IFERROR(CHAR(10)&VLOOKUP(DATE(2027,6,4),Assessments!$H:$I,2,FALSE),CHAR(10)&"Exam day") | O34: 5
A35: 2 | B35: ="3"&CHAR(10)&IFERROR(VLOOKUP(DATE(2027,5,3),Gold!$A:$J,10,FALSE),"")&IFERROR(CHAR(10)&VLOOKUP(DATE(2027,5,3),Assessments!$H:$I,2,FALSE),"") | C35: ="4"&CHAR(10)&IFERROR(VLOOKUP(DATE(2027,5,4),Purple!$A:$J,10,FALSE),"")&IFERROR(CHAR(10)&VLOOKUP(DATE(2027,5,4),Assessments!$H:$I,2,FALSE),"") | D35: ="5"&CHAR(10)&IFERROR(VLOOKUP(DATE(2027,5,5),Gold!$A:$J,10,FALSE),"")&IFERROR(CHAR(10)&VLOOKUP(DATE(2027,5,5),Assessments!$H:$I,2,FALSE),"") | E35: ="6"&CHAR(10)&IFERROR(VLOOKUP(DATE(2027,5,6),Purple!$A:$J,10,FALSE),"")&IFERROR(CHAR(10)&VLOOKUP(DATE(2027,5,6),Assessments!$H:$I,2,FALSE),"") | F35: ="7"&CHAR(10)&IFERROR(VLOOKUP(DATE(2027,5,7),Gold!$A:$J,10,FALSE),"")&IFERROR(CHAR(10)&VLOOKUP(DATE(2027,5,7),Assessments!$H:$I,2,FALSE),"") | G35: 8 | I35: 6 | J35: ="7"&IFERROR(CHAR(10)&"P: "&VLOOKUP(DATE(2027,6,7),Purple!$A:$J,10,FALSE),"")&IFERROR(CHAR(10)&"G: "&VLOOKUP(DATE(2027,6,7),Gold!$A:$J,10,FALSE),"")&IFERROR(CHAR(10)&VLOOKUP(DATE(2027,6,7),Assessments!$H:$I,2,FALSE),CHAR(10)&"Exam day") | K35: ="8"&IFERROR(CHAR(10)&"P: "&VLOOKUP(DATE(2027,6,8),Purple!$A:$J,10,FALSE),"")&IFERROR(CHAR(10)&"G: "&VLOOKUP(DATE(2027,6,8),Gold!$A:$J,10,FALSE),"")&IFERROR(CHAR(10)&VLOOKUP(DATE(2027,6,8),Assessments!$H:$I,2,FALSE),CHAR(10)&"Exam day") | L35: 9 | M35: 10 | N35: 11 | O35: 12
A36: 9 | B36: ="10"&CHAR(10)&IFERROR(VLOOKUP(DATE(2027,5,10),Purple!$A:$J,10,FALSE),"")&IFERROR(CHAR(10)&VLOOKUP(DATE(2027,5,10),Assessments!$H:$I,2,FALSE),"") | C36: ="11"&CHAR(10)&IFERROR(VLOOKUP(DATE(2027,5,11),Gold!$A:$J,10,FALSE),"")&IFERROR(CHAR(10)&VLOOKUP(DATE(2027,5,11),Assessments!$H:$I,2,FALSE),"") | D36: ="12"&CHAR(10)&IFERROR(VLOOKUP(DATE(2027,5,12),Purple!$A:$J,10,FALSE),"")&IFERROR(CHAR(10)&VLOOKUP(DATE(2027,5,12),Assessments!$H:$I,2,FALSE),"") | E36: ="13"&CHAR(10)&IFERROR(VLOOKUP(DATE(2027,5,13),Gold!$A:$J,10,FALSE),"")&IFERROR(CHAR(10)&VLOOKUP(DATE(2027,5,13),Assessments!$H:$I,2,FALSE),"") | F36: ="14"&CHAR(10)&IFERROR(VLOOKUP(DATE(2027,5,14),Purple!$A:$J,10,FALSE),"")&IFERROR(CHAR(10)&VLOOKUP(DATE(2027,5,14),Assessments!$H:$I,2,FALSE),"") | G36: 15 | I36: 13 | J36: 14 | K36: 15 | L36: 16 | M36: 17 | N36: 18 | O36: 19
A37: 16 | B37: ="17"&CHAR(10)&IFERROR(VLOOKUP(DATE(2027,5,17),Gold!$A:$J,10,FALSE),"")&IFERROR(CHAR(10)&VLOOKUP(DATE(2027,5,17),Assessments!$H:$I,2,FALSE),"") | C37: ="18"&CHAR(10)&IFERROR(VLOOKUP(DATE(2027,5,18),Purple!$A:$J,10,FALSE),"")&IFERROR(CHAR(10)&VLOOKUP(DATE(2027,5,18),Assessments!$H:$I,2,FALSE),"") | D37: ="19"&CHAR(10)&IFERROR(VLOOKUP(DATE(2027,5,19),Gold!$A:$J,10,FALSE),"")&IFERROR(CHAR(10)&VLOOKUP(DATE(2027,5,19),Assessments!$H:$I,2,FALSE),"") | E37: ="20"&CHAR(10)&IFERROR(VLOOKUP(DATE(2027,5,20),Purple!$A:$J,10,FALSE),"")&IFERROR(CHAR(10)&VLOOKUP(DATE(2027,5,20),Assessments!$H:$I,2,FALSE),"") | F37: ="21"&CHAR(10)&IFERROR(VLOOKUP(DATE(2027,5,21),Gold!$A:$J,10,FALSE),"")&IFERROR(CHAR(10)&VLOOKUP(DATE(2027,5,21),Assessments!$H:$I,2,FALSE),"") | G37: 22 | I37: 20 | J37: 21 | K37: 22 | L37: 23 | M37: 24 | N37: 25 | O37: 26
A38: 23 | B38: ="24"&CHAR(10)&IFERROR(VLOOKUP(DATE(2027,5,24),Purple!$A:$J,10,FALSE),"")&IFERROR(CHAR(10)&VLOOKUP(DATE(2027,5,24),Assessments!$H:$I,2,FALSE),"") | C38: ="25"&CHAR(10)&IFERROR(VLOOKUP(DATE(2027,5,25),Gold!$A:$J,10,FALSE),"")&IFERROR(CHAR(10)&VLOOKUP(DATE(2027,5,25),Assessments!$H:$I,2,FALSE),"") | D38: ="26"&CHAR(10)&IFERROR(VLOOKUP(DATE(2027,5,26),Purple!$A:$J,10,FALSE),"")&IFERROR(CHAR(10)&VLOOKUP(DATE(2027,5,26),Assessments!$H:$I,2,FALSE),"") | E38: ="27"&CHAR(10)&IFERROR(VLOOKUP(DATE(2027,5,27),Gold!$A:$J,10,FALSE),"")&IFERROR(CHAR(10)&VLOOKUP(DATE(2027,5,27),Assessments!$H:$I,2,FALSE),"") | F38: ="28"&CHAR(10)&IFERROR(VLOOKUP(DATE(2027,5,28),Purple!$A:$J,10,FALSE),"")&IFERROR(CHAR(10)&VLOOKUP(DATE(2027,5,28),Assessments!$H:$I,2,FALSE),"") | G38: 29 | I38: 27 | J38: 28 | K38: 29 | L38: 30
A39: 30 | B39: 31

Sheet Lesson Bank
A1: Lesson ID | B1: Unit | C1: Unit title | D1: Lesson | E1: Calendar label | F1: Lesson focus | G1: Learning target | H1: Standards | I1: Essential question | J1: Core resources | K1: Assessment notes | L1: Scheduling note
A2: U1-W1L1 | B2: 1 | C2: Unleashing Influence | D2: Week 1, Lesson 1 | E2: U1 W1L1 | F2: Understand what opportunities I have in high school. | G2: I will be able to understand what opportunities I have in high school. I will learn the criteria for participating in those opportunities.I will know I am successful when I have identified my goals for high school and the path needed to achieve them. | H2: 9.W.1 9.C.1A.i | I2: How does the influence of media, education, and people shape our view of the world and ourselves? | J2: Slide Deck | K2: Consider the people, events, and media both inside and outside of school (ex: parent, grandparent, godparent, sibling, teacher, pastor, birth, death, graduation, birthday, anniversary, Instagram, TikTok, Snap Chat, Facebook, television, game, or other social media platforms). Explain how one of those elements, whether positively or negatively, has influenced the way you view yourself or the world. Use personal experiences, elaboration, and details to support your essay.
A3: U1-W1L2 | B3: 1 | C3: Unleashing Influence | D3: Week 1, Lesson 2 | E3: U1 W1L2 | F3: Understand the skills and requirements at each grade level needed to pursue a successful high school career. | G3: I will be able to understand the skills and requirements at each grade level needed to pursue a successful high school career. | H3: 9.DSR.A 9.DSR.B 9.RI.1.A 9.C.1A.i | I3: How does the influence of media, education, and people shape our view of the world and ourselves? | J3: Slide Deck
A4: U1-W2L1 | B4: 1 | C4: Unleashing Influence | D4: Week 2, Lesson 1 | E4: U1 W2L1 | F4: Gain an understanding of new vocabulary related to the text The Ravine and review characterization and theme. | G4: Today, I will gain an understanding of new vocabulary related to the text The Ravine and review characterization and theme. I will do this by completing the guided notes. I will know I can do this by using the words in a prediction graphic organizer completing appropriate portions of my story map. | H4: 9.RV.1.G 9.RL.1.A | I4: How does the influence of media, education, and people shape our view of the world and ourselves? | J4: Slide Deck
A5: U1-W2L2 | B5: 1 | C5: Unleashing Influence | D5: Week 2, Lesson 2 | E5: U1 W2L2 | F5: Read and analyze the short story The Ravine. | G5: Today, I will read and analyze the short story The Ravine. I will do this to understand the development of characters and themes in a story.I will know I can do this when I can successfully answer multiple choice questions and a writing prompt about a fictional text. | H5: 9.DSR C 9.RL.1 A | I5: How does the influence of media, education, and people shape our view of the world and ourselves? | J5: Slide Deck
A6: U1-W2L3 | B6: 1 | C6: Unleashing Influence | D6: Week 2, Lesson 3 | E6: U1 W2L3 | F6: Learn about rhetorical devices and how they are used in persuasive writing.I will know I’ve got it when I can distinguish between ethos, pathos, and logos, identify them in media, and use them in my own writing. | G6: Today, I will learn about rhetorical devices and how they are used in persuasive writing.I will know I’ve got it when I can distinguish between ethos, pathos, and logos, identify them in media, and use them in my own writing. | H6: 9.RV.1A 9.RV.1G | I6: How does the influence of media, education, and people shape our view of the world and ourselves? | J6: Slide Deck
A7: U1-W3L1 | B7: 1 | C7: Unleashing Influence | D7: Week 3, Lesson 1 | E7: U1 W3L1 | F7: Compare perspectives and viewpoints of two or more authors to analyze the use of persuasion in various texts. | G7: Today I will compare perspectives and viewpoints of two or more authors to analyze the use of persuasion in various texts. I’ll know I have it when I can discuss thoughtfully with my classmates, answer questions, and complete a Venn Diagram about the two texts. | H7: 9.RI.3.A | I7: How does the influence of media, education, and people shape our view of the world and ourselves? | J7: Slide Deck
A8: U1-W3L2 | B8: 1 | C8: Unleashing Influence | D8: Week 3, Lesson 2 | E8: U1 W3L2 | F8: Use my understanding of persuasive devices to identify ethos, pathos, logos and other persuasive techniques in Old Major’s speech from the novel Animal Farm. | G8: By the end of class today, I will be able to use my understanding of persuasive devices to identify ethos, pathos, logos and other persuasive techniques in Old Major’s speech from the novel Animal Farm. I’ll know I’ve got it when I can correctly identify at least one example of ethos, pathos, and logos in Old Major’s speech and in print ads. | H8: 9.DSR.B 9.DSR.A 9.RI.2.B 9.RI.2.C | I8: How does the influence of media, education, and people shape our view of the world and ourselves? | J8: Slide Deck
A9: U1-W4L1 | B9: 1 | C9: Unleashing Influence | D9: Week 4, Lesson 1 | E9: U1 W4L1 | F9: Read excerpts from George Orwell's novel Animal Farm to analyze persuasive devices, poetic devices, and how a literary form’s structure contributes to meaning. | G9: Today I will read excerpts from George Orwell's novel Animal Farm to analyze persuasive devices, poetic devices, and how a literary form’s structure contributes to meaning. I’ll know I have it when I can identify and explain the impact of rhetorical and poetic devices , and form, in Squeaker’s Speech from Animal Farm. | H9: 9.RI.2.B-C | I9: How does the influence of media, education, and people shape our view of the world and ourselves? | J9: Slide Deck
A10: U1-W4L2 | B10: 1 | C10: Unleashing Influence | D10: Week 4, Lesson 2 | E10: U1 W4L2 | F10: Learn key elements to evaluate clarity and accuracy in informational texts. | G10: Today, I will learn key elements to evaluate clarity and accuracy in informational texts. I’ll know I’ve got it when I am able to use my evaluation document and evaluate a text for clarity and accuracy. | H10: 9.RI.3 | I10: How does the influence of media, education, and people shape our view of the world and ourselves? | J10: Slide Deck
A11: U1-W4L3 | B11: 1 | C11: Unleashing Influence | D11: Week 4, Lesson 3 | E11: U1 W4L3 | F11: Use my knowledge of writing and grammar. | G11: Today, I will use my knowledge of writing and grammar. I’ll know I’ve got it when I am able to write a strong narrative essay, including a thesis, a central idea with evidence, and organized ideas. | H11: 9.W.2.A.i-iii | I11: How does the influence of media, education, and people shape our view of the world and ourselves? | J11: Slide Deck
A12: U1-W5L1 | B12: 1 | C12: Unleashing Influence | D12: Week 5, Lesson 1 | E12: U1 W5L1 | F12: Examine the writing rubric in greater detail, along with the writer’s checklist, so that I can know how to get a good writing score. | G12: Today, I will examine the writing rubric in greater detail, along with the writer’s checklist, so that I can know how to get a good writing score. I’ll know I’ve got it when I can engage in a Writer’s Workshop where I use the rubric, writer’s checklist, and the PEE (Point, Example, Explanation) structure to revise my baseline, type it into No Red Ink , and improve my score. | H12: 9.W.2.A 9.W.3.B | I12: How does the influence of media, education, and people shape our view of the world and ourselves? | J12: Slide Deck
A13: U1-W5L2 | B13: 1 | C13: Unleashing Influence | D13: Week 5, Lesson 2 | E13: U1 W5L2 | F13: Apply my learning of concepts, texts, and skills from Unit 1. | G13: Today, I will apply my learning of concepts, texts, and skills from Unit 1. I’ll know I’ve got it when I can select two items from the Choice Board to apply my learning from Unit 1. | H13: 9.W.1 | I13: How does the influence of media, education, and people shape our view of the world and ourselves? | J13: Slide Deck
A14: U2-C1L1 | B14: 2 | C14: Challenge Accepted! | D14: Cycle 1, Lesson 1 | E14: U2 C1L1 | F14: Participate in a gallery walk, read Ancient Greece: The Birthplace of Western individualism, and answer multiple choice questions. | G14: Today I will participate in a gallery walk, read Ancient Greece: The Birthplace of Western individualism, and answer multiple choice questions. By the end of class, I will show my understanding of the cultural function of mythological figures by using details from the text to correctly answer short response and multiple choice questions. | H14: 9.RL.3A 9.C.1.A.i, iii, iv, v 9.W.1.C | I14: How do the challenges of life affect a person? | J14: Slide Deck | K14: Compare and contrast two characters from one or more anchor texts. How are these characters alike/different in how they face/respond to/overcome challenges? Develop your ideas using specific reasons and examples from the texts you’ve studied.
A15: U2-C1L2 | B15: 2 | C15: Challenge Accepted! | D15: Cycle 1, Lesson 2 | E15: U2 C1L2 | F15: Learn about The Odyssey while taking guided notes, try to survive The Odyssey as a king or crew member, and complete a reading and writing assignment. | G15: Today I will learn about The Odyssey while taking guided notes, try to survive The Odyssey as a king or crew member, and complete a reading and writing assignment. By the end of class, I will show my understanding of how ancient Greek culture shaped Odysseus’s storytelling by analyzing Odysseus’ introduction using information I will learn in this powerpoint and writing my own introduction in the style of The Odyssey. | H15: 9.RL.3.A 9.W.1.C | I15: How do the challenges of life affect a person? | J15: Slide Deck
A16: U2-C1L3 | B16: 2 | C16: Challenge Accepted! | D16: Cycle 1, Lesson 3 | E16: U2 C1L3 | F16: Read the Lotus Eaters Episode of The Odyssey. | G16: Today I will read the Lotus Eaters Episode of The Odyssey. As I am reading I will annotate for character traits, plot, and unknown words. By the end of class, I will show my understanding of how character traits and setting drive the development of the plot in the text though using specific details in my annotations and Facing Challenges Character Tracker. | H16: 9.RL.1.A 9.W.1.C | I16: How do the challenges of life affect a person? | J16: Slide Deck
A17: U2-C1L4 | B17: 2 | C17: Challenge Accepted! | D17: Cycle 1, Lesson 4 | E17: U2 C1L4 | F17: Read and discuss the Cyclops episode of the Odyssey. | G17: Today I will read and discuss the Cyclops episode of the Odyssey. I will fill out a question chart while I read. I’ll know I have it when I can demonstrate my comprehension by reading the text, answering the questions and participating in discussions. | H17: 9.DSR 9.RV.1.B 9.RL.1.A 9.RL.2.B 9.W.1.C | I17: How do the challenges of life affect a person? | J17: Slide Deck
A18: U2-C1L5 | B18: 2 | C18: Challenge Accepted! | D18: Cycle 1, Lesson 5 | E18: U2 C1L5 | F18: Read and discuss the Sirens, Scylla and Charybdis episode of the Odyssey. | G18: Today I will read and discuss the Sirens, Scylla and Charybdis episode of the Odyssey. I will also participate in a Silent Conversation with my classmates. I’ll know I have it when I can demonstrate my comprehension by reading the text, answering the questions, participating in discussions and completing my exit ticket. | H18: 9.DSR, 9.RV.1.B, 9.RL.1.A 9.RL.2.B | I18: How do the challenges of life affect a person? | J18: Slide Deck
A19: U2-C2L1 | B19: 2 | C19: Challenge Accepted! | D19: Cycle 2, Lesson 1 | E19: U2 C2L1 | F19: Read The Odyssey to explain the relationships between setting, characters, and plot and their impact on theme. | G19: Today I will read The Odyssey to explain the relationships between setting, characters, and plot and their impact on theme. I will know I can do this when I answer my guiding questions for my reading and engage in discussion about this episode of The Odyssey with my classmates and connect setting, characters, and plot to a theme from the text. | H19: 9.RV.1 9.W.1.C | I19: How do the challenges of life affect a person? | J19: Slide Deck
A20: U2-C2L2 | B20: 2 | C20: Challenge Accepted! | D20: Cycle 2, Lesson 2 | E20: U2 C2L2 | F20: Read The Odyssey for word choice and tone and how that shapes a text. | G20: Today I will read The Odyssey for word choice and tone and how that shapes a text. I will know I can do this when I answer my guiding questions for my reading, complete my Character Tracker, and identify how word choice and tone shapes today’s reading. | H20: 9.RV.1 9.RL.2.B 9.W.1.C | I20: How do the challenges of life affect a person? | J20: Slide Deck
A21: U2-C2L3 | B21: 2 | C21: Challenge Accepted! | D21: Cycle 2, Lesson 3 | E21: U2 C2L3 | F21: Complete my Common Assessment Tracker and review the tenants of the comparison contrast essay in preparation for writing my Unit 2 Common Assessment. | G21: Today, I will complete my Common Assessment Tracker and review the tenants of the comparison contrast essay in preparation for writing my Unit 2 Common Assessment. I will know I’ve got it when I can use my writing organizer, Common Assessment Tracker, and my notes on writing to develop the thesis statement and introductory paragraph for my common assessment. | H21: 9.RL.1A | I21: How do the challenges of life affect a person? | J21: Slide Deck
A22: U2-C2L4 | B22: 2 | C22: Challenge Accepted! | D22: Cycle 2, Lesson 4 | E22: U2 C2L4 | F22: Complete my Common Assessment Tracker and review the tenants of the comparison contrast essay in preparation for writing my Unit 2 Common Assessment. | G22: Today, I will complete my Common Assessment Tracker and review the tenants of the comparison contrast essay in preparation for writing my Unit 2 Common Assessment. I will know I’ve got it when I can use my writing organizer, Common Assessment Tracker, and my notes on writing to develop the thesis statement and introductory paragraph for my common assessment. | H22: 9.RL.1.A, 9.W.1.A.i-iv, 9.W.2.A.i-iv | I22: How do the challenges of life affect a person? | J22: Slide Deck
A23: U2-C2L5 | B23: 2 | C23: Challenge Accepted! | D23: Cycle 2, Lesson 5 | E23: U2 C2L5 | F23: Read and analyze a commencement speech by Steve Jobs. | G23: Today, I will read and analyze a commencement speech by Steve Jobs. I will do this to analyze the development of the main idea. I will also finalize my common assessment rough draft. I will know I have it when I can summarize key details from the speech that support its main idea and complete a rough draft of my common assessment. | H23: 9.RV.1A, 9.RI.1A, 9.C.4.A-B, 9.W.1.a.i-iv | I23: How do the challenges of life affect a person? | J23: Slide Deck
A24: U2-C3L1 | B24: 2 | C24: Challenge Accepted! | D24: Cycle 3, Lesson 1 | E24: U2 C3L1 | F24: Use my rough draft and my notes to type a final draft of my common assessment into No Red Ink. | G24: Today, I will use my rough draft and my notes to type a final draft of my common assessment into No Red Ink. I’ll know I’ve got it when I successfully type my common assessment into No Red Ink, review my work for grammar and punctuation, and ensure that I’ve completed my best writing. | H24: 9.W.1.a.i-iv | I24: How do the challenges of life affect a person? | J24: Slide Deck
A25: U3-C1L1 | B25: 3 | C25: The Drive to Deceive | D25: Cycle 1, Lesson 1 | E25: U3 C1L1 | F25: Learn about the culture and author of Romeo and Juliet, complete an anticipation guide, and read and annotate the prologue to Romeo and Juliet. | G25: Today I will learn about the culture and author of Romeo and Juliet, complete an anticipation guide, and read and annotate the prologue to Romeo and Juliet. I will track the characteristics of drama in a notes catcher. By the end of class, I will show my ability to identify literary devices in the Prologue of Romeo and Juliet by annotating | H25: 9.RL.1.C 9.RL.2.B 9.RL.2.C 9.RL.2.D | I25: What drives people to deceive others? | J25: Slide Deck | K25: Common Assessment: Many works of literature contain a character who intentionally deceives others. The character’s dishonesty may be intended to help in some cases.But there are times when the character’s dishonesty is used for the purpose of hurting another person. Choose a text from this unit in which a character deceives another character. In a well-written essay, analyze the motives for that character’s deception, and discuss how the deception contributes to the meaning of the text as a whole. Use specific reasons and detailed examples in your essay.
A26: U3-C1L2 | B26: 3 | C26: The Drive to Deceive | D26: Cycle 1, Lesson 2 | E26: U3 C1L2 | F26: Read and annotate Act I, Scenes 1 and 2 of Romeo and Juliet.. | G26: Today I will read and annotate Act I, Scenes 1 and 2 of Romeo and Juliet.. As I am reading, I will annotate the text for literary devices, main ideas, and theme. By the end of class, I will show my understanding of foreshadowing, theme, plot, and additional literary devices through my Act 1, Scene 1 and 2 annotations, study guide questions, and multiple choice questions. | H26: 9.RL.1.C 9.RL.2.B 9.RL.2.C 9.RL.2.D | I26: What drives people to deceive others? | J26: Slide Deck
A27: U3-C1L3 | B27: 3 | C27: The Drive to Deceive | D27: Cycle 1, Lesson 3 | E27: U3 C1L3 | F27: Read Act 1, Scene 5 of Romeo and Juliet and learn about the different types of irony. | G27: Today, I will read Act 1, Scene 5 of Romeo and Juliet and learn about the different types of irony. As I am reading, I will keep track of character actions and literary elements using the Act 1 Scene 5 worksheet. By the end of class, I will be able to show my understanding by summarizing important events through incorporating relevant facts and details into my written response in the Act 1, Scene 5 worksheet. | H27: 9.DSR.A 9.DSR.E 9.W.1 9.RL.2 | I27: What drives people to deceive others? | J27: Slide Deck
A28: U3-C1L4 | B28: 3 | C28: The Drive to Deceive | D28: Cycle 1, Lesson 4 | E28: U3 C1L4 | F28: Read The Act 2 Prologue and Act 2 Scene 2 of Romeo and Juliet. | G28: Today, I will read The Act 2 Prologue and Act 2 Scene 2 of Romeo and Juliet. As I am reading I will annotate the text for literary devices, main ideas, and theme. By the end of class, I will show my understanding by incorporating a thesis statement and adding specific details from the text while effectively incorporating persuasive techniques into the Romeo and Juliet RAFT writing. | H28: 9.W.1.C 9.W.1 9.RL.1.D | I28: What drives people to deceive others? | J28: Slide Deck
A29: U3-C1L5 | B29: 3 | C29: The Drive to Deceive | D29: Cycle 1, Lesson 5 | E29: U3 C1L5 | F29: Read Acts 2, Scene 3 and Act 2, Scene 4 of Romeo and Juliet. | G29: Today, I will read Acts 2, Scene 3 and Act 2, Scene 4 of Romeo and Juliet. As I’m reading, I will keep track of character types and plot progression with my worksheet and notes catcher. By the end of class, I will show my understanding by identifying how dynamic and flat characters in Romeo and Juliet interactions shape the plot in the Act 2, Scene 3 and Act 2, Scene 4. | H29: 9.RL.1C 9.RL.3B | I29: What drives people to deceive others? | J29: Slide Deck
A30: U3-C2L1 | B30: 3 | C30: The Drive to Deceive | D30: Cycle 2, Lesson 1 | E30: U3 C2L1 | F30: Read Act 2 Scene 6 and Act 3 Scene 1 of Romeo and Juliet. | G30: Today I will read Act 2 Scene 6 and Act 3 Scene 1 of Romeo and Juliet. As I am reading, I will annotate the text for literary devices, main ideas, and theme. By the end of class, I will show my understanding by summarizing important events in the Verona Times Newspaper Article by including specific details and quotes from the text, as well as using a variety of sentence structures to help make my writing clear and engaging for the audience. | H30: 9.W.1.C 9.LU.1.B 9.W.1.A 9.W.WC | I30: What drives people to deceive others? | J30: Slide Deck
A31: U3-C2L2 | B31: 3 | C31: The Drive to Deceive | D31: Cycle 2, Lesson 2 | E31: U3 C2L2 | F31: Read select scenes from Act 4 of Romeo and Juliet. | G31: Today I will read select scenes from Act 4 of Romeo and Juliet. As I am reading, I will keep track of important details using the Act 4 Scene 1 & 2 worksheet and my Deception Tracker. I will also brainstorm ideas using a mindmap. By the end of class, I will show my understanding of planning and organizing my writing by completing my deception tracker and my mind maps. | H31: 9.W.2A | I31: What drives people to deceive others? | J31: Slide Deck
A32: U3-C2L3 | B32: 3 | C32: The Drive to Deceive | D32: Cycle 2, Lesson 3 | E32: U3 C2L3 | F32: Read Act 5 Scene 3 of Romeo and Juliet. | G32: Today I will read Act 5 Scene 3 of Romeo and Juliet. As I am reading, I will annotate the text for literary devices, main ideas, and theme. By the end of class today, I will show my understanding of planning and organizing my writing by developing a thesis and incorporating relevant facts, concrete details, and quotations into my draft on Unit 3’s common assessment essay prompt. | H32: 9.W.1.Aiv 9.W.2Ai 9.W.2.Aii | I32: What drives people to deceive others? | J32: Slide Deck
A33: U3-C2L4 | B33: 3 | C33: The Drive to Deceive | D33: Cycle 2, Lesson 4 | E33: U3 C2L4 | F33: Read The Necklace by Guy de Maupassant. | G33: Today, I will read The Necklace by Guy de Maupassant. As I am reading, I will keep track of plot progression with my worksheet. By the end of class today, I will be able to analyze how themes of deception and truth are developed throughout The Necklace by providing specific textual evidence in The Necklace Worksheet and applying my analysis in the multiple choice questions. | H33: 9.RL.1A 9.RL.3B | I33: What drives people to deceive others? | J33: Slide Deck
A34: U3-C2L5 | B34: 3 | C34: The Drive to Deceive | D34: Cycle 2, Lesson 5 | E34: U3 C2L5 | F34: Learn poetic devices, then read and annotate “Siren Song” by Margaret Atwood | G34: Today I will complete my mid-quarter assessment in Studentvue. I will also learn about poetic devices before reading and annotating the poem Siren Song by Margaret Atwood. By the end of class today, I will show my understanding of poetic devices and character motivations through my annotations and short answers in the Siren Song worksheet. | H34: 9.RL.2.C | I34: What drives people to deceive others? | J34: Slide Deck | L34: The mid-quarter assessment in this lesson now has its own full day.
A35: U3-C3L1 | B35: 3 | C35: The Drive to Deceive | D35: Cycle 3, Lesson 1 | E35: U3 C3L1 | F35: Write my final draft of my essay on deception. | G35: Today I will write my final draft of my essay on deception. I will use the text, my deception tracker, my deception mind map, my draft, and my feedback to compose my final essay. By the end of class today, I will show my understanding of planning and organizing my writing, including a clear thesis statement, maintaining a central idea, and incorporating specific details into my response by incorporating all of those aspects into my final essay. | H35: 9.W.3 9.W.2.A 9.W.1iii | I35: What drives people to deceive others? | J35: Slid e Deck
A36: U4-C1L1 | B36: 4 | C36: Through Thick and Thin | D36: Cycle 1, Lesson 1 | E36: U4 C1L1 | F36: Analyze My Father’s Song.” I will do this to explaining author’s craft and style. | G36: Today, I will analyze My Father’s Song.” I will do this to explaining author’s craft and style. I will know I understand what I am learning when I independently read “My Papa’s Waltz” and correctly identify uses of author’s craft and perspective, and elaborate on my claims using textual evidence. | H36: 9.RL.2 AB 9.DSR C | I36: What makes relationships so complex? | J36: Slide Deck | K36: A theme is a universal idea, lesson, or message explored throughout a work of literature. Choose a theme and write an essay to persuade which two texts in this unit exemplify that theme. Consider how characters, plot, setting, tone, and/or point of view help develop the theme. Develop your ideas using specific reasons and examples from the texts you’ve selected.
A37: U4-C1L2 | B37: 4 | C37: Through Thick and Thin | D37: Cycle 1, Lesson 2 | E37: U4 C1L2 | F37: Read Reunion to analyze author’s style and craft. | G37: Today, I will read Reunion to analyze author’s style and craft. I will also learn about appositives and how they introduce clarifying information. I will know I understand what I am learning when I analyze plot, characters, and author’s style and craft in text-dependent questions about Reunion. | H37: 9.DSR.A&E 9.LU.E 9.RL.3B | I37: What makes relationships so complex? | J37: Slide Deck
A38: U4-C1L3 | B38: 4 | C38: Through Thick and Thin | D38: Cycle 1, Lesson 3 | E38: U4 C1L3 | F38: Compare the perspectives and viewpoints of two or more authors on their treatment of similar topics. | G38: Today, I will compare the perspectives and viewpoints of two or more authors on their treatment of similar topics. I will know I understand what I am learning when I can compose a persuasive writing piece that reflects my comprehension of “Papa’s Waltz” and Reunion. | H38: 9.RL.3B 9.RI.3A | I38: What makes relationships so complex? | J38: Slide Deck
A39: U4-C1L4 | B39: 4 | C39: Through Thick and Thin | D39: Cycle 1, Lesson 4 | E39: U4 C1L4 | F39: Compare the perspectives of two or more authors on their treatment of similar topics. | G39: Today, I will compare the perspectives of two or more authors on their treatment of similar topics. I will know I understand what I am learning when I complete a comparison organizer for “Children,” “The Possessive,” and “Parents’ Choice vs. Children’s Dreams” that includes details about the theme, perspective, and word choice from all three texts. | H39: 9.RL.3B 9.RI.3A | I39: What makes relationships so complex? | J39: Slide Deck
A40: U4-C1L5 | B40: 4 | C40: Through Thick and Thin | D40: Cycle 1, Lesson 5 | E40: U4 C1L5 | F40: Review the texts and concepts that I have read so far in Unit 4 to prepare for my Common Assessment. | G40: Today, I will review the texts and concepts that I have read so far in Unit 4 to prepare for my Common Assessment. I will know I understand what I am learning when I complete my brainstorm theme organizer for my Common Assessment. | H40: 9.DSR C 9.RL.3B 9.W.1.ii | I40: What makes relationships so complex? | J40: Slide Deck
...

Sheet Purple
A1: Date | B1: Day | C1: Quarter | D1: Class # | E1: Lesson ID | F1: Unit | G1: Lesson | H1: Lesson focus | I1: Standards | J1: Calendar label | K1: Calendar notes | L1: My notes
A2: 46258 | B2: Mon | C2: Q1 | D2: =ROW()-1 | E2: U1-W1L1+2 | F2: =IFERROR(VLOOKUP($E2,'Lesson Bank'!$A:$L,3,FALSE)&"","") | G2: =IFERROR(VLOOKUP($E2,'Lesson Bank'!$A:$L,4,FALSE)&"","") | H2: =IFERROR(VLOOKUP($E2,'Lesson Bank'!$A:$L,6,FALSE)&"","") | I2: =IFERROR(VLOOKUP($E2,'Lesson Bank'!$A:$L,8,FALSE)&"","") | J2: =IFERROR(VLOOKUP($E2,'Lesson Bank'!$A:$L,5,FALSE),$E2) | K2: First day of school
A3: 46260 | B3: Wed | C3: Q1 | D3: =ROW()-1 | E3: U1-W2L1 | F3: =IFERROR(VLOOKUP($E3,'Lesson Bank'!$A:$L,3,FALSE)&"","") | G3: =IFERROR(VLOOKUP($E3,'Lesson Bank'!$A:$L,4,FALSE)&"","") | H3: =IFERROR(VLOOKUP($E3,'Lesson Bank'!$A:$L,6,FALSE)&"","") | I3: =IFERROR(VLOOKUP($E3,'Lesson Bank'!$A:$L,8,FALSE)&"","") | J3: =IFERROR(VLOOKUP($E3,'Lesson Bank'!$A:$L,5,FALSE),$E3)
A4: 46262 | B4: Fri | C4: Q1 | D4: =ROW()-1 | E4: U1-W2L2 | F4: =IFERROR(VLOOKUP($E4,'Lesson Bank'!$A:$L,3,FALSE)&"","") | G4: =IFERROR(VLOOKUP($E4,'Lesson Bank'!$A:$L,4,FALSE)&"","") | H4: =IFERROR(VLOOKUP($E4,'Lesson Bank'!$A:$L,6,FALSE)&"","") | I4: =IFERROR(VLOOKUP($E4,'Lesson Bank'!$A:$L,8,FALSE)&"","") | J4: =IFERROR(VLOOKUP($E4,'Lesson Bank'!$A:$L,5,FALSE),$E4)
A5: 46266 | B5: Tue | C5: Q1 | D5: =ROW()-1 | E5: U1-W2L3 | F5: =IFERROR(VLOOKUP($E5,'Lesson Bank'!$A:$L,3,FALSE)&"","") | G5: =IFERROR(VLOOKUP($E5,'Lesson Bank'!$A:$L,4,FALSE)&"","") | H5: =IFERROR(VLOOKUP($E5,'Lesson Bank'!$A:$L,6,FALSE)&"","") | I5: =IFERROR(VLOOKUP($E5,'Lesson Bank'!$A:$L,8,FALSE)&"","") | J5: =IFERROR(VLOOKUP($E5,'Lesson Bank'!$A:$L,5,FALSE),$E5)
